Workbook

Sheet MRP
A1: OCTOBER 2026 Aerosol Required Orders | I1: Date: | J1: =TODAY() -> 46303
A2: Dia | B2: Customer | C2: Product Name | D2: Product ID | E2: Job Order # | F2: Required Qty | G2: Produced | H2: Remaining Balance | I2: Remarks
A3: 45 | B3: Phantom Client / Trial Run | C3: Aerosol Can 45x140mm | D3: 9001 | E3: - | F3: 150000 | G3: 0 | H3: =F3-G3 -> 150000 | I3: Commissioning Trial Run (45x140mm @ 5.5mm Slug | Baseline: White/Gold/Glossy)
E4: TOTAL: | F4: =SUM(F3:F3) -> 150000 | G4: =SUM(G3:G3) -> 0 | H4: =SUMIF(H3:H3, ">0") -> 150000
A5: OCTOBER AEROSOL MATERIAL REQUIREMENT PLAN
A6: Item ID | B6: Category | C6: Item Name | D6: UOM | E6: Scrap / Waste % (Editable) | F6: Required Qty (Gross) | G6: Current Stock (Store + WIP) | H6: Surplus / (Deficit) | I6: Current Stock Pieces Can Produce | J6: Status | K6: Product Name(s) | L6: Selection Remarks (Only 1 Needed)
A7: 501 | B7: SLUG | C7: 45mm Slug (5.5mm Thickness, Al 99.7%) | D7: kg | E7: 0.15 | F7: =IF(E7>=1, 0, ROUND(SUMPRODUCT((TableBOM[Item ID]=A7)*TableBOM[Per 1000 Units]*((SUMIF($D$3:$D$3,TableBOM[Product ID],$H$3:$H$3))>0)*(SUMIF($D$3:$D$3,TableBOM[Product ID],$H$3:$H$3))/1000) / (1 - E7), 2)) -> 4167.88 | G7: =IFERROR(INDEX(TableInventory[Store Balance],MATCH(A7,TableInventory[Item ID],0)),0)+IFERROR(INDEX(TableInventory[WIP],MATCH(A7,TableInventory[Item ID],0)),0) -> 150 | H7: =G7-F7 -> -4017.88 | I7: =IFERROR(IF(F7=0, "-", ROUND(G7*1000/(F7/($H$4/1000)), 0)), "-") -> 5398 | J7: =IF(F7=0,"Not needed",IF(H7<0,"SHORTAGE",IF(H7<F7*0.1,"LOW","OK"))) -> SHORTAGE | K7: =IF(LEN(IF((COUNTIFS(TableBOM[Product ID],$D$3,TableBOM[Item ID],$A7)>0)*($H$3>0),$C$3&", ",""))>1,LEFT(IF((COUNTIFS(TableBOM[Product ID],$D$3,TableBOM[Item ID],$A7)>0)*($H$3>0),$C$3&", ",""),LEN(IF((COUNTIFS(TableBOM[Product ID],$D$3,TableBOM[Item ID],$A7)>0)*($H$3>0),$C$3&", ",""))-2),"") -> Aerosol Can 45x140mm | L7: Primary Slug (0.40mm Wall) — Choose 5.5mm OR 6.5mm: only 1 needed
A8: 500 | B8: SLUG | C8: 45mm Slug (6.5mm Thickness, Heavy Wall) | D8: kg | E8: 0.15 | F8: =IF(E8>=1, 0, ROUND(SUMPRODUCT((TableBOM[Item ID]=A8)*TableBOM[Per 1000 Units]*((SUMIF($D$3:$D$3,TableBOM[Product ID],$H$3:$H$3))>0)*(SUMIF($D$3:$D$3,TableBOM[Product ID],$H$3:$H$3))/1000) / (1 - E8), 2)) -> 4925.65 | G8: =IFERROR(INDEX(TableInventory[Store Balance],MATCH(A8,TableInventory[Item ID],0)),0)+IFERROR(INDEX(TableInventory[WIP],MATCH(A8,TableInventory[Item ID],0)),0) -> 65 | H8: =G8-F8 -> -4860.65 | I8: =IFERROR(IF(F8=0, "-", ROUND(G8*1000/(F8/($H$4/1000)), 0)), "-") -> 1979 | J8: =IF(F8=0,"Not needed",IF(H8<0,"SHORTAGE",IF(H8<F8*0.1,"LOW","OK"))) -> SHORTAGE | K8: =IF(LEN(IF((COUNTIFS(TableBOM[Product ID],$D$3,TableBOM[Item ID],$A8)>0)*($H$3>0),$C$3&", ",""))>1,LEFT(IF((COUNTIFS(TableBOM[Product ID],$D$3,TableBOM[Item ID],$A8)>0)*($H$3>0),$C$3&", ",""),LEN(IF((COUNTIFS(TableBOM[Product ID],$D$3,TableBOM[Item ID],$A8)>0)*($H$3>0),$C$3&", ",""))-2),"") -> Aerosol Can 45x140mm | L8: Alternate Slug (Heavy Wall) — Choose 5.5mm OR 6.5mm: only 1 needed
A9: 502 | B9: LUBRICANT | C9: Zinc Powder / SAPILUB LUBRIMET GR8 | D9: kg | E9: 0.15 | F9: =IF(E9>=1, 0, ROUND(SUMPRODUCT((TableBOM[Item ID]=A9)*TableBOM[Per 1000 Units]*((SUMIF($D$3:$D$3,TableBOM[Product ID],$H$3:$H$3))>0)*(SUMIF($D$3:$D$3,TableBOM[Product ID],$H$3:$H$3))/1000) / (1 - E9), 2)) -> 4.38 | G9: =IFERROR(INDEX(TableInventory[Store Balance],MATCH(A9,TableInventory[Item ID],0)),0)+IFERROR(INDEX(TableInventory[WIP],MATCH(A9,TableInventory[Item ID],0)),0) -> 2 | H9: =G9-F9 -> -2.38 | I9: =IFERROR(IF(F9=0, "-", ROUND(G9*1000/(F9/($H$4/1000)), 0)), "-") -> 68493 | J9: =IF(F9=0,"Not needed",IF(H9<0,"SHORTAGE",IF(H9<F9*0.1,"LOW","OK"))) -> SHORTAGE | K9: =IF(LEN(IF((COUNTIFS(TableBOM[Product ID],$D$3,TableBOM[Item ID],$A9)>0)*($H$3>0),$C$3&", ",""))>1,LEFT(IF((COUNTIFS(TableBOM[Product ID],$D$3,TableBOM[Item ID],$A9)>0)*($H$3>0),$C$3&", ",""),LEN(IF((COUNTIFS(TableBOM[Product ID],$D$3,TableBOM[Item ID],$A9)>0)*($H$3>0),$C$3&", ",""))-2),"") -> Aerosol Can 45x140mm | L9: Mandatory Extrusion Lubricant (105g / 100kg slugs tumbled)
A10: 504 | B10: LACQUER | C10: SCHEKOSOL INT PROT Gold (400 9 901) | D10: kg | E10: 0.1 | F10: =IF(E10>=1, 0, ROUND(SUMPRODUCT((TableBOM[Item ID]=A10)*TableBOM[Per 1000 Units]*((SUMIF($D$3:$D$3,TableBOM[Product ID],$H$3:$H$3))>0)*(SUMIF($D$3:$D$3,TableBOM[Product ID],$H$3:$H$3))/1000) / (1 - E10), 2)) -> 153.83 | G10: =IFERROR(INDEX(TableInventory[Store Balance],MATCH(A10,TableInventory[Item ID],0)),0)+IFERROR(INDEX(TableInventory[WIP],MATCH(A10,TableInventory[Item ID],0)),0) -> 30 | H10: =G10-F10 -> -123.83 | I10: =IFERROR(IF(F10=0, "-", ROUND(G10*1000/(F10/($H$4/1000)), 0)), "-") -> 29253 | J10: =IF(F10=0,"Not needed",IF(H10<0,"SHORTAGE",IF(H10<F10*0.1,"LOW","OK"))) -> SHORTAGE | K10: =IF(LEN(IF((COUNTIFS(TableBOM[Product ID],$D$3,TableBOM[Item ID],$A10)>0)*($H$3>0),$C$3&", ",""))>1,LEFT(IF((COUNTIFS(TableBOM[Product ID],$D$3,TableBOM[Item ID],$A10)>0)*($H$3>0),$C$3&", ",""),LEN(IF((COUNTIFS(TableBOM[Product ID],$D$3,TableBOM[Item ID],$A10)>0)*($H$3>0),$C$3&", ",""))-2),"") -> Aerosol Can 45x140mm | L10: Primary Internal Lining (Gold) — Choose Gold OR Beige: only 1 needed
A11: 505 | B11: LACQUER | C11: SCHEKOSOL INT BEIGE (400 4 902) | D11: kg | E11: 0.1 | F11: =IF(E11>=1, 0, ROUND(SUMPRODUCT((TableBOM[Item ID]=A11)*TableBOM[Per 1000 Units]*((SUMIF($D$3:$D$3,TableBOM[Product ID],$H$3:$H$3))>0)*(SUMIF($D$3:$D$3,TableBOM[Product ID],$H$3:$H$3))/1000) / (1 - E11), 2)) -> 167.83 | G11: =IFERROR(INDEX(TableInventory[Store Balance],MATCH(A11,TableInventory[Item ID],0)),0)+IFERROR(INDEX(TableInventory[WIP],MATCH(A11,TableInventory[Item ID],0)),0) -> 0 | H11: =G11-F11 -> -167.83 | I11: =IFERROR(IF(F11=0, "-", ROUND(G11*1000/(F11/($H$4/1000)), 0)), "-") -> 0 | J11: =IF(F11=0,"Not needed",IF(H11<0,"SHORTAGE",IF(H11<F11*0.1,"LOW","OK"))) -> SHORTAGE | K11: =IF(LEN(IF((COUNTIFS(TableBOM[Product ID],$D$3,TableBOM[Item ID],$A11)>0)*($H$3>0),$C$3&", ",""))>1,LEFT(IF((COUNTIFS(TableBOM[Product ID],$D$3,TableBOM[Item ID],$A11)>0)*($H$3>0),$C$3&", ",""),LEN(IF((COUNTIFS(TableBOM[Product ID],$D$3,TableBOM[Item ID],$A11)>0)*($H$3>0),$C$3&", ",""))-2),"") -> Aerosol Can 45x140mm | L11: Alternate Internal Lining (Beige) — Choose Gold OR Beige: only 1 needed
A12: 506 9 901 | B12: THINNER | C12: SCHEKOSOL Reducer 506 9 901 (Lacquer) | D12: kg | E12: 0.2 | F12: =IF(E12>=1, 0, ROUND(SUMPRODUCT((TableBOM[Item ID]=A12)*TableBOM[Per 1000 Units]*((SUMIF($D$3:$D$3,TableBOM[Product ID],$H$3:$H$3))>0)*(SUMIF($D$3:$D$3,TableBOM[Product ID],$H$3:$H$3))/1000) / (1 - E12), 2)) -> 5.18 | G12: =IFERROR(INDEX(TableInventory[Store Balance],MATCH(A12,TableInventory[Item ID],0)),0)+IFERROR(INDEX(TableInventory[WIP],MATCH(A12,TableInventory[Item ID],0)),0) -> 0 | H12: =G12-F12 -> -5.18 | I12: =IFERROR(IF(F12=0, "-", ROUND(G12*1000/(F12/($H$4/1000)), 0)), "-") -> 0 | J12: =IF(F12=0,"Not needed",IF(H12<0,"SHORTAGE",IF(H12<F12*0.1,"LOW","OK"))) -> SHORTAGE | K12: =IF(LEN(IF((COUNTIFS(TableBOM[Product ID],$D$3,TableBOM[Item ID],$A12)>0)*($H$3>0),$C$3&", ",""))>1,LEFT(IF((COUNTIFS(TableBOM[Product ID],$D$3,TableBOM[Item ID],$A12)>0)*($H$3>0),$C$3&", ",""),LEN(IF((COUNTIFS(TableBOM[Product ID],$D$3,TableBOM[Item ID],$A12)>0)*($H$3>0),$C$3&", ",""))-2),"") -> Aerosol Can 45x140mm | L12: Lacquer Reducer (Doubled rate: viscosity regulation + gun & lance cleaning)
A13: 506 | B13: BASE COAT | C13: SCHEKOSOL WH BC (422 0 903) White | D13: kg | E13: 0.15 | F13: =IF(E13>=1, 0, ROUND(SUMPRODUCT((TableBOM[Item ID]=A13)*TableBOM[Per 1000 Units]*((SUMIF($D$3:$D$3,TableBOM[Product ID],$H$3:$H$3))>0)*(SUMIF($D$3:$D$3,TableBOM[Product ID],$H$3:$H$3))/1000) / (1 - E13), 2)) -> 150.18 | G13: =IFERROR(INDEX(TableInventory[Store Balance],MATCH(A13,TableInventory[Item ID],0)),0)+IFERROR(INDEX(TableInventory[WIP],MATCH(A13,TableInventory[Item ID],0)),0) -> 15 | H13: =G13-F13 -> -135.18 | I13: =IFERROR(IF(F13=0, "-", ROUND(G13*1000/(F13/($H$4/1000)), 0)), "-") -> 14982 | J13: =IF(F13=0,"Not needed",IF(H13<0,"SHORTAGE",IF(H13<F13*0.1,"LOW","OK"))) -> SHORTAGE | K13: =IF(LEN(IF((COUNTIFS(TableBOM[Product ID],$D$3,TableBOM[Item ID],$A13)>0)*($H$3>0),$C$3&", ",""))>1,LEFT(IF((COUNTIFS(TableBOM[Product ID],$D$3,TableBOM[Item ID],$A13)>0)*($H$3>0),$C$3&", ",""),LEN(IF((COUNTIFS(TableBOM[Product ID],$D$3,TableBOM[Item ID],$A13)>0)*($H$3>0),$C$3&", ",""))-2),"") -> Aerosol Can 45x140mm | L13: Primary Ground Coat (White) — Choose White OR Clear: only 1 needed
A14: 507 | B14: BASE COAT | C14: SCHEKOSOL CLEAR BC (422 9 918) Clear | D14: kg | E14: 0.15 | F14: =IF(E14>=1, 0, ROUND(SUMPRODUCT((TableBOM[Item ID]=A14)*TableBOM[Per 1000 Units]*((SUMIF($D$3:$D$3,TableBOM[Product ID],$H$3:$H$3))>0)*(SUMIF($D$3:$D$3,TableBOM[Product ID],$H$3:$H$3))/1000) / (1 - E14), 2)) -> 108.35 | G14: =IFERROR(INDEX(TableInventory[Store Balance],MATCH(A14,TableInventory[Item ID],0)),0)+IFERROR(INDEX(TableInventory[WIP],MATCH(A14,TableInventory[Item ID],0)),0) -> 0 | H14: =G14-F14 -> -108.35 | I14: =IFERROR(IF(F14=0, "-", ROUND(G14*1000/(F14/($H$4/1000)), 0)), "-") -> 0 | J14: =IF(F14=0,"Not needed",IF(H14<0,"SHORTAGE",IF(H14<F14*0.1,"LOW","OK"))) -> SHORTAGE | K14: =IF(LEN(IF((COUNTIFS(TableBOM[Product ID],$D$3,TableBOM[Item ID],$A14)>0)*($H$3>0),$C$3&", ",""))>1,LEFT(IF((COUNTIFS(TableBOM[Product ID],$D$3,TableBOM[Item ID],$A14)>0)*($H$3>0),$C$3&", ",""),LEN(IF((COUNTIFS(TableBOM[Product ID],$D$3,TableBOM[Item ID],$A14)>0)*($H$3>0),$C$3&", ",""))-2),"") -> Aerosol Can 45x140mm | L14: Alternate Ground Coat (Clear) — Choose White OR Clear: only 1 needed
A15: 506 9 003 | B15: THINNER | C15: SCHEKOSOL Reducer 506 9 003 (Coating) | D15: kg | E15: 0.2 | F15: =IF(E15>=1, 0, ROUND(SUMPRODUCT((TableBOM[Item ID]=A15)*TableBOM[Per 1000 Units]*((SUMIF($D$3:$D$3,TableBOM[Product ID],$H$3:$H$3))>0)*(SUMIF($D$3:$D$3,TableBOM[Product ID],$H$3:$H$3))/1000) / (1 - E15), 2)) -> 6.9 | G15: =IFERROR(INDEX(TableInventory[Store Balance],MATCH(A15,TableInventory[Item ID],0)),0)+IFERROR(INDEX(TableInventory[WIP],MATCH(A15,TableInventory[Item ID],0)),0) -> 0 | H15: =G15-F15 -> -6.9 | I15: =IFERROR(IF(F15=0, "-", ROUND(G15*1000/(F15/($H$4/1000)), 0)), "-") -> 0 | J15: =IF(F15=0,"Not needed",IF(H15<0,"SHORTAGE",IF(H15<F15*0.1,"LOW","OK"))) -> SHORTAGE | K15: =IF(LEN(IF((COUNTIFS(TableBOM[Product ID],$D$3,TableBOM[Item ID],$A15)>0)*($H$3>0),$C$3&", ",""))>1,LEFT(IF((COUNTIFS(TableBOM[Product ID],$D$3,TableBOM[Item ID],$A15)>0)*($H$3>0),$C$3&", ",""),LEN(IF((COUNTIFS(TableBOM[Product ID],$D$3,TableBOM[Item ID],$A15)>0)*($H$3>0),$C$3&", ",""))-2),"") -> Aerosol Can 45x140mm | L15: Coating Reducer (Doubled rate: viscosity regulation + roller pan washing & cleaning)
A16: 508 | B16: VARNISH | C16: SCHEKOSOL OPV GLOSSY (422 9 900) | D16: kg | E16: 0.15 | F16: =IF(E16>=1, 0, ROUND(SUMPRODUCT((TableBOM[Item ID]=A16)*TableBOM[Per 1000 Units]*((SUMIF($D$3:$D$3,TableBOM[Product ID],$H$3:$H$3))>0)*(SUMIF($D$3:$D$3,TableBOM[Product ID],$H$3:$H$3))/1000) / (1 - E16), 2)) -> 66.35 | G16: =IFERROR(INDEX(TableInventory[Store Balance],MATCH(A16,TableInventory[Item ID],0)),0)+IFERROR(INDEX(TableInventory[WIP],MATCH(A16,TableInventory[Item ID],0)),0) -> 2 | H16: =G16-F16 -> -64.35 | I16: =IFERROR(IF(F16=0, "-", ROUND(G16*1000/(F16/($H$4/1000)), 0)), "-") -> 4521 | J16: =IF(F16=0,"Not needed",IF(H16<0,"SHORTAGE",IF(H16<F16*0.1,"LOW","OK"))) -> SHORTAGE | K16: =IF(LEN(IF((COUNTIFS(TableBOM[Product ID],$D$3,TableBOM[Item ID],$A16)>0)*($H$3>0),$C$3&", ",""))>1,LEFT(IF((COUNTIFS(TableBOM[Product ID],$D$3,TableBOM[Item ID],$A16)>0)*($H$3>0),$C$3&", ",""),LEN(IF((COUNTIFS(TableBOM[Product ID],$D$3,TableBOM[Item ID],$A16)>0)*($H$3>0),$C$3&", ",""))-2),"") -> Aerosol Can 45x140mm | L16: Primary Topcoat (Glossy) — Choose Glossy OR Silk-Matt: only 1 needed
A17: 509 | B17: VARNISH | C17: SCHEKOSOL OPV SILKMATT (422 9 903) | D17: kg | E17: 0.15 | F17: =IF(E17>=1, 0, ROUND(SUMPRODUCT((TableBOM[Item ID]=A17)*TableBOM[Per 1000 Units]*((SUMIF($D$3:$D$3,TableBOM[Product ID],$H$3:$H$3))>0)*(SUMIF($D$3:$D$3,TableBOM[Product ID],$H$3:$H$3))/1000) / (1 - E17), 2)) -> 59.29 | G17: =IFERROR(INDEX(TableInventory[Store Balance],MATCH(A17,TableInventory[Item ID],0)),0)+IFERROR(INDEX(TableInventory[WIP],MATCH(A17,TableInventory[Item ID],0)),0) -> 0 | H17: =G17-F17 -> -59.29 | I17: =IFERROR(IF(F17=0, "-", ROUND(G17*1000/(F17/($H$4/1000)), 0)), "-") -> 0 | J17: =IF(F17=0,"Not needed",IF(H17<0,"SHORTAGE",IF(H17<F17*0.1,"LOW","OK"))) -> SHORTAGE | K17: =IF(LEN(IF((COUNTIFS(TableBOM[Product ID],$D$3,TableBOM[Item ID],$A17)>0)*($H$3>0),$C$3&", ",""))>1,LEFT(IF((COUNTIFS(TableBOM[Product ID],$D$3,TableBOM[Item ID],$A17)>0)*($H$3>0),$C$3&", ",""),LEN(IF((COUNTIFS(TableBOM[Product ID],$D$3,TableBOM[Item ID],$A17)>0)*($H$3>0),$C$3&", ",""))-2),"") -> Aerosol Can 45x140mm | L17: Alternate Topcoat (Silk-Matt) — Choose Glossy OR Silk-Matt: only 1 needed
A18: 608 | B18: INK | C18: SunAltec MB PLUS Cyan (168400) | D18: kg | E18: 0.125 | F18: =IF(E18>=1, 0, ROUND(SUMPRODUCT((TableBOM[Item ID]=A18)*TableBOM[Per 1000 Units]*((SUMIF($D$3:$D$3,TableBOM[Product ID],$H$3:$H$3))>0)*(SUMIF($D$3:$D$3,TableBOM[Product ID],$H$3:$H$3))/1000) / (1 - E18), 2)) -> 42 | G18: =IFERROR(INDEX(TableInventory[Store Balance],MATCH(A18,TableInventory[Item ID],0)),0)+IFERROR(INDEX(TableInventory[WIP],MATCH(A18,TableInventory[Item ID],0)),0) -> 2.2 | H18: =G18-F18 -> -39.8 | I18: =IFERROR(IF(F18=0, "-", ROUND(G18*1000/(F18/($H$4/1000)), 0)), "-") -> 7857 | J18: =IF(F18=0,"Not needed",IF(H18<0,"SHORTAGE",IF(H18<F18*0.1,"LOW","OK"))) -> SHORTAGE | K18: =IF(LEN(IF((COUNTIFS(TableBOM[Product ID],$D$3,TableBOM[Item ID],$A18)>0)*($H$3>0),$C$3&", ",""))>1,LEFT(IF((COUNTIFS(TableBOM[Product ID],$D$3,TableBOM[Item ID],$A18)>0)*($H$3>0),$C$3&", ",""),LEN(IF((COUNTIFS(TableBOM[Product ID],$D$3,TableBOM[Item ID],$A18)>0)*($H$3>0),$C$3&", ",""))-2),"") -> Aerosol Can 45x140mm | L18: UV Offset Cyan (Station 1 — 17 vacuum tins of 2.5 kg)
... A22: 503 | B22: CLEANER | C22: SAPILUB ALULIQUID 13 (Washer Chem) | D22: kg | E22: 0.15 | F22: =IF(E22>=1, 0, ROUND(SUMPRODUCT((TableBOM[Item ID]=A22)*TableBOM[Per 1000 Units]*((SUMIF($D$3:$D$3,TableBOM[Product ID],$H$3:$H$3))>0)*(SUMIF($D$3:$D$3,TableBOM[Product ID],$H$3:$H$3))/1000) / (1 - E22), 2)) -> 882.35 | G22: =IFERROR(INDEX(TableInventory[Store Balance],MATCH(A22,TableInventory[Item ID],0)),0)+IFERROR(INDEX(TableInventory[WIP],MATCH(A22,TableInventory[Item ID],0)),0) -> 50 | H22: =G22-F22 -> -832.35 | I22: =IFERROR(IF(F22=0, "-", ROUND(G22*1000/(F22/($H$4/1000)), 0)), "-") -> 8500 | J22: =IF(F22=0,"Not needed",IF(H22<0,"SHORTAGE",IF(H22<F22*0.1,"LOW","OK"))) -> SHORTAGE | K22: =IF(LEN(IF((COUNTIFS(TableBOM[Product ID],$D$3,TableBOM[Item ID],$A22)>0)*($H$3>0),$C$3&", ",""))>1,LEFT(IF((COUNTIFS(TableBOM[Product ID],$D$3,TableBOM[Item ID],$A22)>0)*($H$3>0),$C$3&", ",""),LEN(IF((COUNTIFS(TableBOM[Product ID],$D$3,TableBOM[Item ID],$A22)>0)*($H$3>0),$C$3&", ",""))-2),"") -> Aerosol Can 45x140mm | L22: Washer Chemical initial bath charge buffer

Sheet Inventory
A1: AEROSOL RAW MATERIAL INVENTORY LEDGER (PLANT STORE + WIP) | I1: Date: | J1: =TODAY() -> 46303
A2: Item ID | B2: Category | C2: Item Name (ERP) | D2: UOM | E2: Opening | F2: Received | G2: Issued | H2: Store Balance | I2: WIP | J2: Total Stock | K2: Pieces Can Produce
A3: 501 | B3: SLUG | C3: 45mm Slug (5.5mm Thickness, Al 99.7%) | D3: kg | E3: 150 | F3: 0 | G3: 0 | H3: =E3+F3-G3 -> 150 | I3: 0 | J3: =H3+I3 -> 150 | K3: =IFERROR(INDEX(MRP!$I$7:$I$25, MATCH(A3, MRP!$A$7:$A$25, 0)), "-") -> 5398
A4: 500 | B4: SLUG | C4: 45mm Slug (6.5mm Thickness, Heavy Wall) | D4: kg | E4: 65 | F4: 0 | G4: 0 | H4: =E4+F4-G4 -> 65 | I4: 0 | J4: =H4+I4 -> 65 | K4: =IFERROR(INDEX(MRP!$I$7:$I$25, MATCH(A4, MRP!$A$7:$A$25, 0)), "-") -> 1979
A5: 502 | B5: LUBRICANT | C5: Zinc Powder / SAPILUB LUBRIMET GR8 | D5: kg | E5: 2 | F5: 0 | G5: 0 | H5: =E5+F5-G5 -> 2 | I5: 0 | J5: =H5+I5 -> 2 | K5: =IFERROR(INDEX(MRP!$I$7:$I$25, MATCH(A5, MRP!$A$7:$A$25, 0)), "-") -> 68493
A6: 504 | B6: LACQUER | C6: SCHEKOSOL INT PROT Gold (400 9 901) | D6: kg | E6: 30 | F6: 0 | G6: 0 | H6: =E6+F6-G6 -> 30 | I6: 0 | J6: =H6+I6 -> 30 | K6: =IFERROR(INDEX(MRP!$I$7:$I$25, MATCH(A6, MRP!$A$7:$A$25, 0)), "-") -> 29253
A7: 505 | B7: LACQUER | C7: SCHEKOSOL INT BEIGE (400 4 902) | D7: kg | E7: 0 | F7: 0 | G7: 0 | H7: =E7+F7-G7 -> 0 | I7: 0 | J7: =H7+I7 -> 0 | K7: =IFERROR(INDEX(MRP!$I$7:$I$25, MATCH(A7, MRP!$A$7:$A$25, 0)), "-") -> 0
A8: 506 9 901 | B8: THINNER | C8: SCHEKOSOL Reducer 506 9 901 (Lacquer) | D8: kg | E8: 0 | F8: 0 | G8: 0 | H8: =E8+F8-G8 -> 0 | I8: 0 | J8: =H8+I8 -> 0 | K8: =IFERROR(INDEX(MRP!$I$7:$I$25, MATCH(A8, MRP!$A$7:$A$25, 0)), "-") -> 0
A9: 506 | B9: BASE COAT | C9: SCHEKOSOL WH BC (422 0 903) White | D9: kg | E9: 15 | F9: 0 | G9: 0 | H9: =E9+F9-G9 -> 15 | I9: 0 | J9: =H9+I9 -> 15 | K9: =IFERROR(INDEX(MRP!$I$7:$I$25, MATCH(A9, MRP!$A$7:$A$25, 0)), "-") -> 14982
A10: 507 | B10: BASE COAT | C10: SCHEKOSOL CLEAR BC (422 9 918) Clear | D10: kg | E10: 0 | F10: 0 | G10: 0 | H10: =E10+F10-G10 -> 0 | I10: 0 | J10: =H10+I10 -> 0 | K10: =IFERROR(INDEX(MRP!$I$7:$I$25, MATCH(A10, MRP!$A$7:$A$25, 0)), "-") -> 0
A11: 506 9 003 | B11: THINNER | C11: SCHEKOSOL Reducer 506 9 003 (Coating) | D11: kg | E11: 0 | F11: 0 | G11: 0 | H11: =E11+F11-G11 -> 0 | I11: 0 | J11: =H11+I11 -> 0 | K11: =IFERROR(INDEX(MRP!$I$7:$I$25, MATCH(A11, MRP!$A$7:$A$25, 0)), "-") -> 0
A12: 508 | B12: VARNISH | C12: SCHEKOSOL OPV GLOSSY (422 9 900) | D12: kg | E12: 2 | F12: 0 | G12: 0 | H12: =E12+F12-G12 -> 2 | I12: 0 | J12: =H12+I12 -> 2 | K12: =IFERROR(INDEX(MRP!$I$7:$I$25, MATCH(A12, MRP!$A$7:$A$25, 0)), "-") -> 4521
A13: 509 | B13: VARNISH | C13: SCHEKOSOL OPV SILKMATT (422 9 903) | D13: kg | E13: 0 | F13: 0 | G13: 0 | H13: =E13+F13-G13 -> 0 | I13: 0 | J13: =H13+I13 -> 0 | K13: =IFERROR(INDEX(MRP!$I$7:$I$25, MATCH(A13, MRP!$A$7:$A$25, 0)), "-") -> 0
A14: 608 | B14: INK | C14: SunAltec MB PLUS Cyan (168400) | D14: kg | E14: 2.2 | F14: 0 | G14: 0 | H14: =E14+F14-G14 -> 2.2 | I14: 0 | J14: =H14+I14 -> 2.2 | K14: =IFERROR(INDEX(MRP!$I$7:$I$25, MATCH(A14, MRP!$A$7:$A$25, 0)), "-") -> 7857
... A20: PKG-PLT | B20: PACKING | C20: Wooden Pallets (3,000 cans/pallet) | D20: PLT | E20: 10 | F20: 0 | G20: 0 | H20: =E20+F20-G20 -> 10 | I20: 0 | J20: =H20+I20 -> 10 | K20: =IFERROR(INDEX(MRP!$I$7:$I$25, MATCH(A20, MRP!$A$7:$A$25, 0)), "-") -> -

Sheet BOM
A1: BILL OF MATERIALS — Customer-Specific Monobloc Aerosol Cans
A2: Product ID | B2: BOM ID | C2: Customer | D2: Product Name | E2: Dia | F2: Material Category | G2: Item ID | H2: Item Name | I2: UOM | J2: Per 1000 Units | K2: Material Group | L2: Scrap % | M2: Change Note
A3: 9001 | B3: 101 | C3: Phantom Client / Trial Run | D3: Aerosol Can 45x140mm | E3: 45 | F3: SLUG | G3: 501 | H3: 45mm Slug (5.5mm Thickness, Al 99.7%) | I3: kg | J3: 23.618 | K3: Aluminum Slugs | L3: 0.15 | M3: Option A Slug (0.40mm Wall) — Choose 5.5mm (501) OR 6.5mm (500): only 1 needed
A4: 9001 | B4: 101 | C4: Phantom Client / Trial Run | D4: Aerosol Can 45x140mm | E4: 45 | F4: SLUG | G4: 500 | H4: 45mm Slug (6.5mm Thickness, Heavy Wall) | I4: kg | J4: 27.912 | K4: Aluminum Slugs | L4: 0.15 | M4: Option B Slug (Heavy Wall) — Choose 5.5mm (501) OR 6.5mm (500): only 1 needed
A5: 9001 | B5: 101 | C5: Phantom Client / Trial Run | D5: Aerosol Can 45x140mm | E5: 45 | F5: LUBRICANT | G5: 502 | H5: Zinc Powder / SAPILUB LUBRIMET GR8 | I5: kg | J5: 0.0248 | K5: Extrusion Lubricant | L5: 0.15 | M5: Mandatory Tumbling Lubricant (TDS p.8: 105g/100kg slugs)
A6: 9001 | B6: 101 | C6: Phantom Client / Trial Run | D6: Aerosol Can 45x140mm | E6: 45 | F6: CLEANER | G6: 503 | H6: SAPILUB ALULIQUID 13 (Washer Chem) | I6: kg | J6: 5 | K6: Alkaline Cleaner | L6: 0.15 | M6: Mandatory Washer Degreaser initial bath charge buffer (TDS p.22)
A7: 9001 | B7: 101 | C7: Phantom Client / Trial Run | D7: Aerosol Can 45x140mm | E7: 45 | F7: LACQUER | G7: 504 | H7: SCHEKOSOL INT PROT Gold (400 9 901) | I7: kg | J7: 0.923 | K7: Internal Lacquer | L7: 0.1 | M7: Option A Internal Lining (Gold) — Choose Gold (504) OR Beige (505): only 1 needed
A8: 9001 | B8: 101 | C8: Phantom Client / Trial Run | D8: Aerosol Can 45x140mm | E8: 45 | F8: LACQUER | G8: 505 | H8: SCHEKOSOL INT BEIGE (400 4 902) | I8: kg | J8: 1.007 | K8: Internal Lacquer | L8: 0.1 | M8: Option B Internal Lining (Beige) — Choose Gold (504) OR Beige (505): only 1 needed
A9: 9001 | B9: 101 | C9: Phantom Client / Trial Run | D9: Aerosol Can 45x140mm | E9: 45 | F9: THINNER | G9: 506 9 901 | H9: SCHEKOSOL Reducer 506 9 901 (Lacquer) | I9: kg | J9: 0.0276 | K9: Solvent Reducer | L9: 0.2 | M9: Doubled rate (0.0276 kg/1k) for viscosity thinning (DIN 4 85s) + lance purging & line cleaning
A10: 9001 | B10: 101 | C10: Phantom Client / Trial Run | D10: Aerosol Can 45x140mm | E10: 45 | F10: BASE COAT | G10: 506 | H10: SCHEKOSOL WH BC (422 0 903) White | I10: kg | J10: 0.851 | K10: External Base Coat | L10: 0.15 | M10: Option A Ground Coat (White) — Choose White (506) OR Clear (507): only 1 needed
A11: 9001 | B11: 101 | C11: Phantom Client / Trial Run | D11: Aerosol Can 45x140mm | E11: 45 | F11: BASE COAT | G11: 507 | H11: SCHEKOSOL CLEAR BC (422 9 918) Clear | I11: kg | J11: 0.614 | K11: External Base Coat | L11: 0.15 | M11: Option B Ground Coat (Clear) — Choose White (506) OR Clear (507): only 1 needed
A12: 9001 | B12: 101 | C12: Phantom Client / Trial Run | D12: Aerosol Can 45x140mm | E12: 45 | F12: THINNER | G12: 506 9 003 | H12: SCHEKOSOL Reducer 506 9 003 (Coating) | I12: kg | J12: 0.0368 | K12: Solvent Reducer | L12: 0.2 | M12: Doubled rate (0.0368 kg/1k) for viscosity thinning (DIN 4 110s) + roller pan washouts & coater cleaning
A13: 9001 | B13: 101 | C13: Phantom Client / Trial Run | D13: Aerosol Can 45x140mm | E13: 45 | F13: VARNISH | G13: 508 | H13: SCHEKOSOL OPV GLOSSY (422 9 900) | I13: kg | J13: 0.376 | K13: Overprint Varnish | L13: 0.15 | M13: Option A Topcoat (Glossy) — Choose Glossy (508) OR Silk-Matt (509): only 1 needed
A14: 9001 | B14: 101 | C14: Phantom Client / Trial Run | D14: Aerosol Can 45x140mm | E14: 45 | F14: VARNISH | G14: 509 | H14: SCHEKOSOL OPV SILKMATT (422 9 903) | I14: kg | J14: 0.336 | K14: Overprint Varnish | L14: 0.15 | M14: Option B Topcoat (Silk-Matt) — Choose Glossy (508) OR Silk-Matt (509): only 1 needed
... A28: 9002 | B28: 102 | C28: Alternate Client / Brushed Finish | D28: Aerosol Can 45x140mm - Beige/Matt | E28: 45 | F28: PACKING | G28: PKG-PLT | H28: Wooden Pallets (3,000 cans/pallet) | I28: PLT | J28: 0.333 | K28: Packaging Logistics | L28: 0.02 | M28: Logistics Pallets

Sheet BOM calculations
A1: ALPHA AEROSOLS — RAW MATERIAL AUDIT & CALCULATION LOGIC
A2: Production Run: 150,000 Cans | Container Size: Ø 45 mm × 140 mm Trimmed Height | Slug: Ø 45.0 mm × 5.5 mm (Al 99.7%)
A5: 1. CONTAINER GEOMETRY & STARTING DIMENSIONS (THE PHYSICAL FOUNDATION)
A6: All calculations originate from physical Euclidean dimensions and the density of pure aluminum (EN AW-1070A = 2.70 g/cm³):
A7: Parameter | B7: Formula | C7: Value | D7: Unit | E7: Source Document / Engineering Note
A8: Slug Diameter | B8: D_slug | C8: 45 | D8: mm | E8: Tooling specification for 45mm cold impact extrusion die
A9: Slug Thickness (Standard) | B9: T_slug | C9: 5.5 | D9: mm | E9: Option A nominal slug thickness for 0.40mm body wall specification
A10: Slug Thickness (Heavy Wall) | B10: T_slug | C10: 6.5 | D10: mm | E10: Option B nominal slug thickness for 0.45mm body wall specification
A11: Trimmed Can Height | B11: H_trim | C11: 140 | D11: mm | E11: User Specified: Trimmer knife cutoff height prior to necking
A12: Slug Net Mass (5.5mm) | B12: Volume × 2.70 g/cm³ | C12: 23.618 | D12: g / slug | E12: Net weight per slug disc = 23.618 kg per 1,000 slugs
A13: Slug Net Mass (6.5mm) | B13: Volume × 2.70 g/cm³ | C13: 27.912 | D13: g / slug | E13: Net weight per slug disc = 27.912 kg per 1,000 slugs
A14: Outside Coater Area | B14: π × D × H | C14: 0.01979 | D14: m² / can | E14: External roller coater surface area (Base coat & Varnish)
A15: Inside Spray Area | B15: Cylinder + Dome | C15: 0.02098 | D15: m² / can | E15: Internal spray lance coverage area (Wall 0.01979 + Dome 0.00118 m²)
A16: Net Slugs for 150k Cans | B16: 150,000 × 23.618g | C16: 3542.7 | D16: kg | E16: Zero-scrap net metal required for 150,000 finished cans (5.5mm slug)
A18: 2. MASTER MATERIAL AUDIT & EXACT DOCUMENT SOURCES (FOR 150,000 CANS)
A19: This table provides exact calculations for BOTH primary and alternative options (only 1 needed per category):
A20: Item Code | B20: Material Name | C20: Net Rate / 1k | D20: Scrap % | E20: Gross Req (150k) | F20: Floor Stock | G20: Deficit | H20: Exact Document Source | I20: Selection Rule & Engineering Logic
A21: 501 | B21: 45mm Slug (5.5mm Thickness) | C21: 23.618 | D21: 0.15 | E21: 4167.88 | F21: 150 | G21: -4017.88 | H21: Tooling Spec & Math | I21: Option A Slug (0.40mm wall). 176,471 slugs needed. Choose 5.5mm OR 6.5mm: only 1 needed.
A22: 500 | B22: 45mm Slug (6.5mm Heavy Wall) | C22: 27.912 | D22: 0.15 | E22: 4925.65 | F22: 65 | G22: -4860.65 | H22: Tooling Spec & Math | I22: Option B Slug (0.45mm wall). 176,471 slugs needed. Choose 5.5mm OR 6.5mm: only 1 needed.
A23: 502 | B23: Zinc Powder / SAPILUB GR8 | C23: 0.0248 | D23: 0.15 | E23: 4.38 | F23: 2 | G23: -2.38 | H23: TDS.pdf, Page 8 | I23: Extrusion lubricant. Dosage spec: 105g per 100kg slugs (tumbled with slugs before extrusion).
A24: 503 | B24: SAPILUB ALULIQUID 13 (Cleaner) | C24: 5 | D24: 0.15 | E24: 882.35 | F24: 50 | G24: -832.35 | H24: TDS.pdf, Page 22 | I24: Alkaline spray degreaser for wash tanks. 5 kg/1000 cans initial tank charge and wash buffer.
A25: 504 | B25: SCHEKOSOL Gold Lacquer (400 9 901) | C25: 0.923 | D25: 0.1 | E25: 153.83 | F25: 30 | G25: -123.83 | H25: TDS.pdf, Page 2 | I25: Option A Internal Lining (Gold). TDS wet film: 44 g/m². Choose Gold OR Beige: only 1 needed.
A26: 505 | B26: SCHEKOSOL Beige Lacquer (400 4 902) | C26: 1.007 | D26: 0.1 | E26: 167.83 | F26: 0 | G26: -167.83 | H26: TDS.pdf, Page 3 | I26: Option B Internal Lining (Beige). TDS wet film: 48 g/m². Choose Gold OR Beige: only 1 needed.
A27: 506 9 901 | B27: Lacquer Thinner (506 9 901) | C27: 0.0276 | D27: 0.2 | E27: 5.18 | F27: 0 | G27: -5.18 | H27: TDS.pdf & SOP Cleaning Rate | I27: Doubled rate (0.0276 kg/1k) covers lacquer viscosity thinning (DIN 4 cup 85s) plus routine airless spray lance purging and nozzle blowouts.
A28: 506 | B28: SCHEKOSOL White Base Coat (422 0 903) | C28: 0.851 | D28: 0.15 | E28: 150.18 | F28: 15 | G28: -135.18 | H28: TDS.pdf, Page 1 | I28: Option A Ground Coat (White). TDS wet film: 43 g/m² (71% solids). Choose White OR Clear: only 1 needed.
A29: 507 | B29: SCHEKOSOL Clear Base Coat (422 9 918) | C29: 0.614 | D29: 0.15 | E29: 108.35 | F29: 0 | G29: -108.35 | H29: TDS.pdf, Page 35 | I29: Option B Ground Coat (Clear). TDS wet film: 31 g/m² (51% solids). Choose White OR Clear: only 1 needed.
A30: 506 9 003 | B30: Base Coat Thinner (506 9 003) | C30: 0.0368 | D30: 0.2 | E30: 6.9 | F30: 0 | G30: -6.9 | H30: TDS.pdf & SOP Cleaning Rate | I30: Doubled rate (0.0368 kg/1k) covers base coat viscosity thinning (DIN 4 cup 110s) plus roller coater pan washouts and doctor blade cleanups.
A31: 508 | B31: SCHEKOSOL OPV Glossy Varnish (422 9 900) | C31: 0.376 | D31: 0.15 | E31: 66.35 | F31: 2 | G31: -64.35 | H31: TDS.pdf, Page 37 | I31: Option A Topcoat (Glossy). TDS wet film: 19 g/m² (43% solids). Choose Glossy OR Silk-Matt: only 1 needed.
A32: 509 | B32: SCHEKOSOL OPV Silk-Matt Varnish (422 9 903) | C32: 0.336 | D32: 0.15 | E32: 59.29 | F32: 0 | G32: -59.29 | H32: TDS.pdf, Page 36 | I32: Option B Topcoat (Silk-Matt). TDS wet film: 17 g/m² (47% solids). Choose Glossy OR Silk-Matt: only 1 needed.
... A38: PKG-PLT | B38: Wooden Pallets (3,000 cans/pallet) | C38: 0.333 | D38: 0.02 | E38: 51 | F38: 10 | G38: -41 | H38: Packaging Standard | I38: 15 boxes per pallet = 3,000 cans/pallet. Gross includes 2% handling allowance.
A40: 3. WHY WE DIVIDE BY (1 - SCRAP) INSTEAD OF MULTIPLYING (MASS BALANCE PHYSICS)
A41: • Common Shop-Floor Mistake (Additive Model): People often calculate: Gross = Net × (1 + Scrap).
A42: - At 15% scrap on 150,000 cans: 150,000 × 1.15 = 172,500 slugs.
A43: - But when 172,500 slugs enter the press, 15% scrap is lost on INPUT: 172,500 × 0.85 = 146,625 cans produced.
A44: - Result: THE LINE RUNS SHORT BY 3,375 CANS, and you cannot fulfill the customer order!
A46: • The Correct Manufacturing Law (Yield-Inverse Model): Scrap happens on TOTAL INPUT, not saleable output.
A47: - Formula: Gross Input = Required Output / (1 - Scrap %)
A48: - Calculation: 150,000 / (1 - 0.15) = 150,000 / 0.85 = 176,471 slugs (4,167.88 kg).
A49: - Floor Verification: 176,471 slugs × 0.85 surviving = EXACTLY 150,000 finished saleable cans.
A51: • Live Scrap Adjustment on MRP Sheet:
...
